<?xml version="1.0" ?>
<robot name="robot">
  <gazebo reference="base_link">
    <material>Gazebo/DarkGrey</material>
    <mu1>0.2</mu1>
    <mu2>0.2</mu2>
    <gravity>true</gravity>
  </gazebo>
  <gazebo reference="FL_Hombro">
    <material>Gazebo/DarkGrey</material>
    <mu1>0.2</mu1>
    <mu2>0.2</mu2>
    <gravity>true</gravity>
  </gazebo>
  <gazebo reference="FL_Brazo">
    <material>Gazebo/DarkGrey</material>
    <mu1>0.2</mu1>
    <mu2>0.2</mu2>
    <selfCollide>true</selfCollide>
    <gravity>true</gravity>
  </gazebo>
  <gazebo reference="FL_Antebrazo">
    <material>Gazebo/DarkGrey</material>
    <mu1>0.2</mu1>
    <mu2>0.2</mu2>
    <selfCollide>true</selfCollide>
    <gravity>true</gravity>
  </gazebo>
  <gazebo reference="RL_Hombro">
    <material>Gazebo/DarkGrey</material>
    <mu1>0.2</mu1>
    <mu2>0.2</mu2>
    <gravity>true</gravity>
  </gazebo>
  <gazebo reference="RL_Brazo">
    <material>Gazebo/DarkGrey</material>
    <mu1>0.2</mu1>
    <mu2>0.2</mu2>
    <selfCollide>true</selfCollide>
    <gravity>true</gravity>
  </gazebo>
  <gazebo reference="RL_Antebrazo">
    <material>Gazebo/DarkGrey</material>
    <mu1>0.2</mu1>
    <mu2>0.2</mu2>
    <selfCollide>true</selfCollide>
    <gravity>true</gravity>
  </gazebo>
  <gazebo reference="RR_Hombro">
    <material>Gazebo/DarkGrey</material>
    <mu1>0.2</mu1>
    <mu2>0.2</mu2>
    <gravity>true</gravity>
  </gazebo>
  <gazebo reference="RR_Brazo">
    <material>Gazebo/DarkGrey</material>
    <mu1>0.2</mu1>
    <mu2>0.2</mu2>
    <selfCollide>true</selfCollide>
    <gravity>true</gravity>
  </gazebo>
  <gazebo reference="RR_Antebrazo">
    <material>Gazebo/DarkGrey</material>
    <mu1>0.2</mu1>
    <mu2>0.2</mu2>
    <selfCollide>true</selfCollide>
    <gravity>true</gravity>
  </gazebo>
  <gazebo reference="FR_Hombro">
    <material>Gazebo/DarkGrey</material>
    <mu1>0.2</mu1>
    <mu2>0.2</mu2>
    <gravity>true</gravity>
  </gazebo>
  <gazebo reference="FR_Brazo">
    <material>Gazebo/DarkGrey</material>
    <mu1>0.2</mu1>
    <mu2>0.2</mu2>
    <selfCollide>true</selfCollide>
    <gravity>true</gravity>
  </gazebo>
  <gazebo reference="FR_Antebrazo">
    <material>Gazebo/DarkGrey</material>
    <mu1>0.2</mu1>
    <mu2>0.2</mu2>
    <selfCollide>true</selfCollide>
    <gravity>true</gravity>
  </gazebo>
  <!-- ===== Gazebo Sim plugins (igual que tu URDF) ===== -->
  <ros2_control name="GazeboSimSystem" type="system">
    <hardware>
      <plugin>gz_ros2_control/GazeboSimSystem</plugin>
    </hardware>
    <!-- Joints -->
    <joint name="Revolution_1">
      <command_interface name="position">
        <param name="min">-45</param>
        <param name="max">45</param>
      </command_interface>
      <state_interface name="position">
        <param name="initial_value">0.0</param>
      </state_interface>
      <state_interface name="velocity"/>
      <state_interface name="effort"/>
    </joint>
    <joint name="Revolution_2">
      <command_interface name="position">
        <param name="min">-45</param>
        <param name="max">45</param>
      </command_interface>
      <state_interface name="position">
        <param name="initial_value">0.0</param>
      </state_interface>
      <state_interface name="velocity"/>
      <state_interface name="effort"/>
    </joint>
    <joint name="Revolution_3">
      <command_interface name="position">
        <param name="min">-45</param>
        <param name="max">45</param>
      </command_interface>
      <state_interface name="position">
        <param name="initial_value">0.0</param>
      </state_interface>
      <state_interface name="velocity"/>
      <state_interface name="effort"/>
    </joint>
    <joint name="Revolution_4">
      <command_interface name="position">
        <param name="min">-45</param>
        <param name="max">45</param>
      </command_interface>
      <state_interface name="position">
        <param name="initial_value">0.0</param>
      </state_interface>
      <state_interface name="velocity"/>
      <state_interface name="effort"/>
    </joint>
    <joint name="Revolution_5">
      <command_interface name="position">
        <param name="min">-45</param>
        <param name="max">45</param>
      </command_interface>
      <state_interface name="position">
        <param name="initial_value">0.0</param>
      </state_interface>
      <state_interface name="velocity"/>
      <state_interface name="effort"/>
    </joint>
    <joint name="Revolution_6">
      <command_interface name="position">
        <param name="min">-45</param>
        <param name="max">45</param>
      </command_interface>
      <state_interface name="position">
        <param name="initial_value">0.0</param>
      </state_interface>
      <state_interface name="velocity"/>
      <state_interface name="effort"/>
    </joint>
    <joint name="Revolution_7">
      <command_interface name="position">
        <param name="min">-45</param>
        <param name="max">45</param>
      </command_interface>
      <state_interface name="position">
        <param name="initial_value">0.0</param>
      </state_interface>
      <state_interface name="velocity"/>
      <state_interface name="effort"/>
    </joint>
    <joint name="Revolution_8">
      <command_interface name="position">
        <param name="min">-45</param>
        <param name="max">45</param>
      </command_interface>
      <state_interface name="position">
        <param name="initial_value">0.0</param>
      </state_interface>
      <state_interface name="velocity"/>
      <state_interface name="effort"/>
    </joint>
    <joint name="Revolution_9">
      <command_interface name="position">
        <param name="min">-45</param>
        <param name="max">45</param>
      </command_interface>
      <state_interface name="position">
        <param name="initial_value">0.0</param>
      </state_interface>
      <state_interface name="velocity"/>
      <state_interface name="effort"/>
    </joint>
    <joint name="Revolution_10">
      <command_interface name="position">
        <param name="min">-45</param>
        <param name="max">45</param>
      </command_interface>
      <state_interface name="position">
        <param name="initial_value">0.0</param>
      </state_interface>
      <state_interface name="velocity"/>
      <state_interface name="effort"/>
    </joint>
    <joint name="Revolution_11">
      <command_interface name="position">
        <param name="min">-45</param>
        <param name="max">45</param>
      </command_interface>
      <state_interface name="position">
        <param name="initial_value">0.0</param>
      </state_interface>
      <state_interface name="velocity"/>
      <state_interface name="effort"/>
    </joint>
    <joint name="Revolution_12">
      <command_interface name="position">
        <param name="min">-45</param>
        <param name="max">45</param>
      </command_interface>
      <state_interface name="position">
        <param name="initial_value">0.0</param>
      </state_interface>
      <state_interface name="velocity"/>
      <state_interface name="effort"/>
    </joint>
  </ros2_control>
  <gazebo>
    <!-- Plugin de ROS 2 Control para Gazebo Sim -->
    <plugin filename="gz_ros2_control-system" name="gz_ros2_control::GazeboSimROS2ControlPlugin">
      <parameters>$(find demo)/config/ros2_control.yaml</parameters>
    </plugin>
  </gazebo>

  <gazebo>
    <plugin filename="libgz-sim-pose-publisher-system"
            name="gz::sim::systems::PosePublisher">
      <publish_link_pose>false</publish_link_pose>
      <publish_nested_model_pose>false</publish_nested_model_pose>
      <use_pose_vector_msg>true</use_pose_vector_msg>
    </plugin>
  </gazebo>

  <!-- ===== IMU (Gazebo Sim) ===== -->
  <gazebo reference="imu_link">
    <sensor name="imu_sensor" type="imu">
      <always_on>true</always_on>
      <update_rate>100.0</update_rate>
      <visualize>true</visualize>
      <topic>imu</topic>
      <gz_frame_id>imu_link</gz_frame_id>
      <plugin filename="gz-sim-imu-system" name="gz::sim::systems::Imu">
        <initial_orientation_as_reference>true</initial_orientation_as_reference>
      </plugin>
    </sensor>
  </gazebo>
  <!-- ===== Mundo/base ===== -->
  <link name="world"/>
  <joint name="fixed_base_joint" type="fixed">
    <parent link="world"/>
    <child link="base_link"/>
    <origin rpy="0 0 0" xyz="0 0 0"/> <!--xyz="0 0 2.35"-->
  </joint>
  <!-- ===== Links con rutas y escalas originales ===== -->
  <link name="base_link">
    <inertial>
      <origin rpy="0 0 0" xyz="0 0 0"/>
      <mass value="0.132259326627842"/>
      <inertia ixx="0.000199" ixy="0.000129" ixz="2e-06" iyy="0.001133" iyz="-3e-06" izz="0.001312"/>
    </inertial>
    <visual>
      <origin rpy="0 0 0" xyz="0 0 0"/>
      <geometry>
        <mesh filename="file:///home/lucia/TFG/robot_quadruped/src/robot_description/meshes/base_link.stl" scale="0.02 0.02 0.02"/>
      </geometry>
    </visual>
    <collision>
      <origin rpy="0 0 0" xyz="0 0 0"/>
      <geometry>
        <mesh filename="file:///home/lucia/TFG/robot_quadruped/src/robot_description/meshes/base_link.stl" scale="0.02 0.02 0.02"/>
      </geometry>
    </collision>
  </link>
  <link name="FL_Antebrazo">
    <inertial>
      <origin rpy="0 0 0" xyz="0 0 0"/>
      <mass value="0.11017130901550822"/>
      <inertia ixx="5e-06" ixy="0" ixz="0" iyy="1.1e-05" iyz="0" izz="6e-06"/>
    </inertial>
    <visual>
      <origin rpy="0 0 0" xyz="-2.275 0.6 -1.49"/>
      <geometry>
        <mesh filename="file:///home/lucia/TFG/robot_quadruped/src/robot_description/meshes/FL_Antebrazo.stl" scale="0.02 0.02 0.02"/>
      </geometry>
    </visual>
    <collision>
      <origin rpy="0 0 0" xyz="-2.275 0.6 -1.49"/>
      <geometry>
        <mesh filename="file:///home/lucia/TFG/robot_quadruped/src/robot_description/meshes/FL_Antebrazo.stl" scale="0.02 0.02 0.02"/>
      </geometry>
    </collision>
  </link>
  <link name="FL_Brazo">
    <inertial>
      <origin rpy="0 0 0" xyz="0 0 0"/>
      <mass value="0.30409136144975923"/>
      <inertia ixx="2.3e-05" ixy="2e-06" ixz="-1.7e-05" iyy="3.7e-05" iyz="2e-06" izz="2.3e-05"/>
    </inertial>
    <visual>
      <origin rpy="0 0 0" xyz="-3.53 1.40795 -2.926598"/>
      <geometry>
        <mesh filename="file:///home/lucia/TFG/robot_quadruped/src/robot_description/meshes/FL_Brazo.stl" scale="0.02 0.02 0.02"/>
      </geometry>
    </visual>
    <collision>
      <origin rpy="0 0 0" xyz="-3.53 1.40795 -2.926598"/>
      <geometry>
        <mesh filename="file:///home/lucia/TFG/robot_quadruped/src/robot_description/meshes/FL_Brazo.stl" scale="0.02 0.02 0.02"/>
      </geometry>
    </collision>
  </link>
  <link name="FL_Hombro">
    <inertial>
      <origin rpy="0 0 0" xyz="0 0 0"/>
      <mass value="0.1859774303312477"/>
      <inertia ixx="4e-06" ixy="-0.0" ixz="-0.0" iyy="3e-06" iyz="-1e-06" izz="4e-06"/>
    </inertial>
    <visual>
      <origin rpy="0 0 0" xyz="-3.6501245 1.8257 -2.90722"/>
      <geometry>
        <mesh filename="file:///home/lucia/TFG/robot_quadruped/src/robot_description/meshes/FL_Hombro.stl" scale="0.02 0.02 0.02"/>
      </geometry>
    </visual>
    <collision>
      <origin rpy="0 0 0" xyz="-3.6501245 1.8257 -2.90722"/>
      <geometry>
        <mesh filename="file:///home/lucia/TFG/robot_quadruped/src/robot_description/meshes/FL_Hombro.stl" scale="0.02 0.02 0.02"/>
      </geometry>
    </collision>
  </link>
  <link name="RL_Antebrazo">
    <inertial>
      <origin rpy="0 0 0" xyz="0 0 0"/>
      <mass value="0.11048026895118968"/>
      <inertia ixx="5e-06" ixy="0" ixz="0" iyy="1.1e-05" iyz="0" izz="6e-06"/>
    </inertial>
    <visual>
      <origin rpy="0 0 0" xyz="1.675 0.1 -1.56"/>
      <geometry>
        <mesh filename="file:///home/lucia/TFG/robot_quadruped/src/robot_description/meshes/RL_Antebrazo.stl" scale="0.02 0.02 0.02"/>
      </geometry>
    </visual>
    <collision>
      <origin rpy="0 0 0" xyz="1.675 0.1 -1.56"/>
      <geometry>
        <mesh filename="file:///home/lucia/TFG/robot_quadruped/src/robot_description/meshes/RL_Antebrazo.stl" scale="0.02 0.02 0.02"/>
      </geometry>
    </collision>
  </link>
  <link name="RL_Brazo">
    <inertial>
      <origin rpy="0 0 0" xyz="0 0 0"/>
      <mass value="0.3040973749415957"/>
      <inertia ixx="2.1e-05" ixy="2e-06" ixz="-1.6e-05" iyy="3.7e-05" iyz="2e-06" izz="2.5e-05"/>
    </inertial>
    <visual>
      <origin rpy="0 0 0" xyz="0.32 0.85 -2.91722"/>
      <geometry>
        <mesh filename="file:///home/lucia/TFG/robot_quadruped/src/robot_description/meshes/RL_Brazo.stl" scale="0.02 0.02 0.02"/>
      </geometry>
    </visual>
    <collision>
      <origin rpy="0 0 0" xyz="0.32 0.85 -2.91722"/>
      <geometry>
        <mesh filename="file:///home/lucia/TFG/robot_quadruped/src/robot_description/meshes/RL_Brazo.stl" scale="0.02 0.02 0.02"/>
      </geometry>
    </collision>
  </link>
  <link name="RL_Hombro">
    <inertial>
      <origin rpy="0 0 0" xyz="0 0 0"/>
      <mass value="0.18594032037447486"/>
      <inertia ixx="4e-06" ixy="-0.0" ixz="-0.0" iyy="3e-06" iyz="-1e-06" izz="4e-06"/>
    </inertial>
    <visual>
      <origin rpy="0 0 0" xyz="0.6 1.23 -2.91722"/>
      <geometry>
        <mesh filename="file:///home/lucia/TFG/robot_quadruped/src/robot_description/meshes/RL_Hombro.stl" scale="0.02 0.02 0.02"/>
      </geometry>
    </visual>
    <collision>
      <origin rpy="0 0 0" xyz="0.6 1.23 -2.91722"/>
      <geometry>
        <mesh filename="file:///home/lucia/TFG/robot_quadruped/src/robot_description/meshes/RL_Hombro.stl" scale="0.02 0.02 0.02"/>
      </geometry>
    </collision>
  </link>
  <link name="RR_Antebrazo">
    <inertial>
      <origin rpy="0 0 0" xyz="0 0 0"/>
      <mass value="0.11048045171812943"/>
      <inertia ixx="5e-06" ixy="-0.0" ixz="5e-06" iyy="1.1e-05" iyz="0.0" izz="7e-06"/>
    </inertial>
    <visual>
      <origin rpy="0 0 0" xyz="2.242 3.66 -1.5"/>
      <geometry>
        <mesh filename="file:///home/lucia/TFG/robot_quadruped/src/robot_description/meshes/RR_Antebrazo.stl" scale="0.02 0.02 0.02"/>
      </geometry>
    </visual>
    <collision>
      <origin rpy="0 0 0" xyz="2.242 3.66 -1.5"/>
      <geometry>
        <mesh filename="file:///home/lucia/TFG/robot_quadruped/src/robot_description/meshes/RR_Antebrazo.stl" scale="0.02 0.02 0.02"/>
      </geometry>
    </collision>
  </link>
  <link name="RR_Brazo">
    <inertial>
      <origin rpy="0 0 0" xyz="0 0 0"/>
      <mass value="0.3040973749415908"/>
      <inertia ixx="2e-05" ixy="5e-06" ixz="-1.6e-05" iyy="3.6e-05" iyz="4e-06" izz="2.7e-05"/>
    </inertial>
    <visual>
      <origin rpy="0 0 0" xyz="0.65 3.5 -2.9"/>
      <geometry>
        <mesh filename="file:///home/lucia/TFG/robot_quadruped/src/robot_description/meshes/RR_Brazo.stl" scale="0.02 0.02 0.02"/>
      </geometry>
    </visual>
    <collision>
      <origin rpy="0 0 0" xyz="0.65 3.5 -2.9"/>
      <geometry>
        <mesh filename="file:///home/lucia/TFG/robot_quadruped/src/robot_description/meshes/RR_Brazo.stl" scale="0.02 0.02 0.02"/>
      </geometry>
    </collision>
  </link>
  <link name="RR_Hombro">
    <inertial>
      <origin rpy="0 0 0" xyz="0 0 0"/>
      <mass value="0.185940356423774"/>
      <inertia ixx="4e-06" ixy="-0.0" ixz="0.0" iyy="3e-06" iyz="0.0" izz="4e-06"/>
    </inertial>
    <visual>
      <origin rpy="0 0 0" xyz="0.84 3.035 -2.9"/>
      <geometry>
        <mesh filename="file:///home/lucia/TFG/robot_quadruped/src/robot_description/meshes/RR_Hombro.stl" scale="0.02 0.02 0.02"/>
      </geometry>
    </visual>
    <collision>
      <origin rpy="0 0 0" xyz="0.84 3.035 -2.9"/>
      <geometry>
        <mesh filename="file:///home/lucia/TFG/robot_quadruped/src/robot_description/meshes/RR_Hombro.stl" scale="0.02 0.02 0.02"/>
      </geometry>
    </collision>
  </link>
  <link name="FR_Antebrazo">
    <inertial>
      <origin rpy="0 0 0" xyz="0 0 0"/>
      <mass value="0.11033575580722182"/>
      <inertia ixx="5e-06" ixy="0" ixz="0" iyy="1.1e-05" iyz="0" izz="6e-06"/>
    </inertial>
    <visual>
      <origin rpy="0 0 0" xyz="-1.655 4.35 -1.43"/>
      <geometry>
        <mesh filename="file:///home/lucia/TFG/robot_quadruped/src/robot_description/meshes/FR_Antebrazo.stl" scale="0.02 0.02 0.02"/>
      </geometry>
    </visual>
    <collision>
      <origin rpy="0 0 0" xyz="-1.655 4.35 -1.43"/>
      <geometry>
        <mesh filename="file:///home/lucia/TFG/robot_quadruped/src/robot_description/meshes/FR_Antebrazo.stl" scale="0.02 0.02 0.02"/>
      </geometry>
    </collision>
  </link>
  <link name="FR_Brazo">
    <inertial>
      <origin rpy="0 0 0" xyz="0 0 0"/>
      <mass value="0.3040973749414956"/>
      <inertia ixx="2.3e-05" ixy="3e-06" ixz="-1.6e-05" iyy="3.7e-05" iyz="3e-06" izz="2.4e-05"/>
    </inertial>
    <visual>
      <origin rpy="0 0 0" xyz="-3.1 4 -2.90722"/>
      <geometry>
        <mesh filename="file:///home/lucia/TFG/robot_quadruped/src/robot_description/meshes/FR_Brazo.stl" scale="0.02 0.02 0.02"/>
      </geometry>
    </visual>
    <collision>
      <origin rpy="0 0 0" xyz="-3.1 4 -2.90722"/>
      <geometry>
        <mesh filename="file:///home/lucia/TFG/robot_quadruped/src/robot_description/meshes/FR_Brazo.stl" scale="0.02 0.02 0.02"/>
      </geometry>
    </collision>
  </link>
  <link name="FR_Hombro">
    <inertial>
      <origin rpy="0 0 0" xyz="0 0 0"/>
      <mass value="0.1859736994896006"/>
      <inertia ixx="4e-06" ixy="-0.0" ixz="0.0" iyy="3e-06" iyz="1e-06" izz="4e-06"/>
    </inertial>
    <visual>
      <origin rpy="0 0 0" xyz="-3.37 3.62 -2.90722"/>
      <geometry>
        <mesh filename="file:///home/lucia/TFG/robot_quadruped/src/robot_description/meshes/FR_Hombro.stl" scale="0.02 0.02 0.02"/>
      </geometry>
    </visual>
    <collision>
      <origin rpy="0 0 0" xyz="-3.37 3.62 -2.90722"/>
      <geometry>
        <mesh filename="file:///home/lucia/TFG/robot_quadruped/src/robot_description/meshes/FR_Hombro.stl" scale="0.02 0.02 0.02"/>
      </geometry>
    </collision>
  </link>
  <!-- IMU link -->
  <link name="imu_link">
    <inertial>
      <origin rpy="0 0 0" xyz="0 0 0"/>
      <mass value="0.1"/>
      <inertia ixx="0.0001" ixy="0.0" ixz="0.0" iyy="0.0001" iyz="0.0" izz="0.0001"/>
    </inertial>
  </link>
  <!-- ===== Joints (idénticos) ===== -->
  <joint name="imu_joint" type="fixed">
    <parent link="base_link"/>
    <child link="imu_link"/>
  </joint>
  <joint name="Revolution_1" type="revolute">
    <origin rpy="0 0 0" xyz="-1.258 0.8 -1.435"/>
    <parent link="FL_Brazo"/>
    <child link="FL_Antebrazo"/>
    <axis xyz="0 -1 0"/>
    <limit effort="10.0" lower="-1.57" upper="1.57" velocity="5.0"/>
    <dynamics damping="0.01" friction="0.1"/>
  </joint>
  <joint name="Revolution_2" type="revolute">
    <origin rpy="0 0 0" xyz="-0.1155 0.415 0.025"/>
    <parent link="FL_Hombro"/>
    <child link="FL_Brazo"/>
    <axis xyz="0 -1 0"/>
    <limit effort="10.0" lower="-1.57" upper="1.57" velocity="5.0"/>
    <dynamics damping="0.01" friction="0.1"/>
  </joint>
  <joint name="Revolution_3" type="revolute">
    <origin rpy="0 0 0" xyz="3.6001245 -1.83513 2.90722"/>
    <parent link="base_link"/>
    <child link="FL_Hombro"/>
    <axis xyz="-1 0 0"/>
    <limit effort="10.0" lower="-1.57" upper="1.57" velocity="5.0"/>
    <dynamics damping="0.01" friction="0.1"/>
  </joint>
  <joint name="Revolution_4" type="revolute">
    <origin rpy="0 0 0" xyz="-1.358 0.75 -1.355"/>
    <parent link="RL_Brazo"/>
    <child link="RL_Antebrazo"/>
    <axis xyz="0 -1 0"/>
    <limit effort="10.0" lower="-1.57" upper="1.57" velocity="5.0"/>
    <dynamics damping="0.01" friction="0.1"/>
  </joint>
  <joint name="Revolution_5" type="revolute">
    <origin rpy="0 0 0" xyz="0.285 0.34 0.01"/>
    <parent link="RL_Hombro"/>
    <child link="RL_Brazo"/>
    <axis xyz="0 -1 0"/>
    <limit effort="10.0" lower="-1.57" upper="1.57" velocity="5.0"/>
    <dynamics damping="0.01" friction="0.1"/>
  </joint>
  <joint name="Revolution_6" type="revolute">
    <origin rpy="0 0 0" xyz="-0.557292 -1.25513 2.91722"/>
    <parent link="base_link"/>
    <child link="RL_Hombro"/>
    <axis xyz="-1 0 0"/>
    <limit effort="10.0" lower="-1.57" upper="1.57" velocity="5.0"/>
    <dynamics damping="0.01" friction="0.1"/>
  </joint>
  <joint name="Revolution_7" type="revolute">
    <origin rpy="0 0 0" xyz="-1.59 -0.15 -1.4"/>
    <parent link="RR_Brazo"/>
    <child link="RR_Antebrazo"/>
    <axis xyz="0 -1 0"/>
    <limit effort="10.0" lower="-1.57" upper="1.57" velocity="5.0"/>
    <dynamics damping="0.01" friction="0.1"/>
  </joint>
  <joint name="Revolution_8" type="revolute">
    <origin rpy="0 0 0" xyz="0.18 -0.415 -0.035"/>
    <parent link="RR_Hombro"/>
    <child link="RR_Brazo"/>
    <axis xyz="0 -1 0"/>
    <limit effort="10.0" lower="-1.57" upper="1.57" velocity="5.0"/>
    <dynamics damping="0.01" friction="0.1"/>
  </joint>
  <joint name="Revolution_9" type="revolute">
    <origin rpy="0 0 0" xyz="-0.8 -3.03 2.9"/>
    <parent link="base_link"/>
    <child link="RR_Hombro"/>
    <axis xyz="1 0 0"/>
    <limit effort="10.0" lower="-1.57" upper="1.57" velocity="5.0"/>
    <dynamics damping="0.01" friction="0.1"/>
  </joint>
  <joint name="Revolution_10" type="revolute">
    <origin rpy="0 0 0" xyz="-1.445 -0.32 -1.48"/>
    <parent link="FR_Brazo"/>
    <child link="FR_Antebrazo"/>
    <axis xyz="0 -1 0"/>
    <limit effort="10.0" lower="-1.57" upper="1.57" velocity="5.0"/>
    <dynamics damping="0.01" friction="0.1"/>
  </joint>
  <joint name="Revolution_11" type="revolute">
    <origin rpy="0 0 0" xyz="-0.27 -0.35 -0.01"/>
    <parent link="FR_Hombro"/>
    <child link="FR_Brazo"/>
    <axis xyz="0 -1 0"/>
    <limit effort="10.0" lower="-1.57" upper="1.57" velocity="5.0"/>
    <dynamics damping="0.01" friction="0.1"/>
  </joint>
  <joint name="Revolution_12" type="revolute">
    <origin rpy="0 0 0" xyz="3.41 -3.61 2.90722"/>
    <parent link="base_link"/>
    <child link="FR_Hombro"/>
    <axis xyz="1 0 0"/>
    <limit effort="10.0" lower="-1.57" upper="1.57" velocity="5.0"/>
    <dynamics damping="0.01" friction="0.1"/>
  </joint>
</robot>
